2023-10-02 19:55:18,310 ERROR scheduler Exception in Enqueue Events for Site ride.local
Traceback (most recent call last):
  File "/home/mohan360ithub/frappe-course/env/lib/python3.10/site-packages/pymysql/connections.py", line 644, in connect
    sock = socket.create_connection(
  File "/usr/lib/python3.10/socket.py", line 845, in create_connection
    raise err
  File "/usr/lib/python3.10/socket.py", line 833, in create_connection
    sock.connect(sa)
ConnectionRefusedError: [Errno 111] Connection refused

During handling of the above exception, another exception occurred:

Traceback (most recent call last):
  File "/home/mohan360ithub/frappe-course/apps/frappe/frappe/utils/scheduler.py", line 73, in enqueue_events_for_site
    if is_scheduler_inactive():
  File "/home/mohan360ithub/frappe-course/apps/frappe/frappe/utils/scheduler.py", line 110, in is_scheduler_inactive
    if is_scheduler_disabled(verbose=verbose):
  File "/home/mohan360ithub/frappe-course/apps/frappe/frappe/utils/scheduler.py", line 123, in is_scheduler_disabled
    frappe.db.get_single_value("System Settings", "enable_scheduler")
  File "/home/mohan360ithub/frappe-course/apps/frappe/frappe/database/database.py", line 776, in get_single_value
    ).run()
  File "/home/mohan360ithub/frappe-course/apps/frappe/frappe/query_builder/utils.py", line 87, in execute_query
    result = frappe.db.sql(query, params, *args, **kwargs)  # nosemgrep
  File "/home/mohan360ithub/frappe-course/apps/frappe/frappe/database/database.py", line 194, in sql
    self.connect()
  File "/home/mohan360ithub/frappe-course/apps/frappe/frappe/database/database.py", line 109, in connect
    self._conn = self.get_connection()
  File "/home/mohan360ithub/frappe-course/apps/frappe/frappe/database/mariadb/database.py", line 102, in get_connection
    conn = self._get_connection()
  File "/home/mohan360ithub/frappe-course/apps/frappe/frappe/database/mariadb/database.py", line 108, in _get_connection
    return self.create_connection()
  File "/home/mohan360ithub/frappe-course/apps/frappe/frappe/database/mariadb/database.py", line 111, in create_connection
    return pymysql.connect(**self.get_connection_settings())
  File "/home/mohan360ithub/frappe-course/env/lib/python3.10/site-packages/pymysql/connections.py", line 358, in __init__
    self.connect()
  File "/home/mohan360ithub/frappe-course/env/lib/python3.10/site-packages/pymysql/connections.py", line 711, in connect
    raise exc
pymysql.err.OperationalError: (2003, "Can't connect to MySQL server on '127.0.0.1' ([Errno 111] Connection refused)")
